Workbook

Sheet README
A1: Literature Review Workbook: ML/DL Intrusion Detection for IoT (CICIoT2023 focus)
A3: Companion to the literature review paper. Covers 20 studies: 8 reviews/surveys, 11 experimental studies, 1 benchmark.
A4: The author's own experiments are on This_Study and are not counted in the 20 studies.
A6: Sheets:
A7: Summary - formula-driven counts and charts.
A8: Studies - one row per study with extraction fields and theme flags (1 = theme covered).
A9: Reviews - comparison of the 8 reviews and surveys.
A10: Datasets - datasets used and how many included studies list each.
A11: Gaps - research gaps and the studies that raise them.
A12: References - citations for the 20 studies.
A13: This_Study - the author's own deep-learning experiments (MLP, GRU, LSTM, Transformer): setup, results, theme flags and relation to the gaps.
A15: Legend: blue text = value or judgement entered by me from the papers (or, on This_Study, from my notebook output); black = formula or label.
... A26: 9. Theme flags and gap statuses on This_Study are my judgement, like the flags on Studies.

Sheet Summary
A1: Summary of the 20-study corpus
A3: Measure | B3: Value
A4: Total studies | B4: =COUNTA(Studies!B2:B21) -> 20
A5: Reviews and surveys | B5: =COUNTIF(Studies!F2:F21,"Review")+COUNTIF(Studies!F2:F21,"Survey")+COUNTIF(Studies!F2:F21,"Systematic review") -> 8
A6: Experimental studies | B6: =COUNTIF(Studies!F2:F21,"Experimental") -> 11
A7: Benchmark studies | B7: =COUNTIF(Studies!F2:F21,"Benchmark") -> 1
A8: Studies published 2024 | B8: =COUNTIF(Studies!C2:C21,2024) -> 2
A9: Studies published 2025 | B9: =COUNTIF(Studies!C2:C21,2025) -> 9
A10: Studies published 2026 | B10: =COUNTIF(Studies!C2:C21,2026) -> 8
A11: Studies with no stated date | B11: =COUNTIF(Studies!C2:C21,"n.d.") -> 1
A12: Peer-reviewed journal articles | B12: =COUNTIF(Studies!G2:G21,"Peer-reviewed journal") -> 16
A13: Not standard journal articles | B13: =B4-B12 -> 4
A14: Experimental studies using CICIoT2023 | B14: =COUNTIFS(Studies!F2:F21,"Experimental",Studies!L2:L21,"Yes") -> 10
A15: Share of experimental studies using CICIoT2023 | B15: =B14/B6 -> 0.90909091
A16: Average themes covered per study | B16: =AVERAGE(Studies!U2:U21) -> 3.7
A17: Total research gaps listed | B17: =COUNTA(Gaps!B2:B12) -> 11
A20: Theme coverage
A21: Theme | B21: Studies covering it | C21: Share of corpus
A22: ML / ensembles | B22: =SUM(Studies!M2:M21) -> 17 | C22: =B22/$B$4 -> 0.85
A23: Deep learning | B23: =SUM(Studies!N2:N21) -> 12 | C23: =B23/$B$4 -> 0.6
A24: Explainable AI | B24: =SUM(Studies!O2:O21) -> 5 | C24: =B24/$B$4 -> 0.25
A25: Federated / privacy | B25: =SUM(Studies!P2:P21) -> 5 | C25: =B25/$B$4 -> 0.25
A26: Adversarial robustness | B26: =SUM(Studies!Q2:Q21) -> 5 | C26: =B26/$B$4 -> 0.25
A27: Class imbalance | B27: =SUM(Studies!R2:R21) -> 10 | C27: =B27/$B$4 -> 0.5
A28: Edge / efficiency | B28: =SUM(Studies!S2:S21) -> 7 | C28: =B28/$B$4 -> 0.35
A29: Multiple datasets / benchmarking | B29: =SUM(Studies!T2:T21) -> 13 | C29: =B29/$B$4 -> 0.65
A31: Year distribution
A32: Year | B32: Studies
A33: 2024 | B33: =B8 -> 2
A34: 2025 | B34: =B9 -> 9
A35: 2026 | B35: =B10 -> 8
A37: Own experiments (this study) are on This_Study and are not included in these counts.

Sheet Paper_Summaries
A1: ID | B1: Study | C1: Year | D1: Aim | E1: Method and data | F1: Main results | G1: Main limitation
A2: 1 | B2: Poltoratskyi & Gavrylenko | C2: 2026 | D2: Review the evolution of IDS from 2020 to 2025. | E2: Taxonomy by detection method, deployment, data source and response; analysis of modern datasets (ROAD, Edge-IIoT-2022, CICIoT2023, CICIoMT2024, CREMEv2, RT-IoT2022) and of ML, DL, hybrid and federated approaches. | F2: Accuracy above 98% is common on benchmarks, but imbalance, zero-day detection, scalability and privacy remain open; recommends MCC, F1, AUC-PR and operational metrics. | G2: Narrative synthesis; no screening counts reported.
A3: 2 | B3: Rivandi & Oskouei | C3: 2025 | D3: Detect attacks in mobile social (ad hoc) networks. | E3: Social-network metrics (betweenness, degree) in ego networks with a normal profile and a two-standard-deviation threshold; NS2 simulation, 30 nodes, AODV, four attacks (packet drop, black hole, sleep deprivation, TCP SYN). | F3: Single-node detection 99.8-99.9%; detection delay 0.424 s vs 1.051 s for an Apriori-based IDS; fewer rules. | G3: Small simulation; no IoT benchmark data; multi-node detection only 40-61%.
A4: 3 | B4: Meena & Indian | C4: 2025 | D4: Compare IDS methods across datasets with an enhanced LSTM. | E4: Two LSTM layers of 100 units, flatten and softmax output, 20 epochs, Adam; compared with logistic regression, AdaBoost, DNN, RNN on KDD-Cup'99, NSL-KDD, UNSW-NB15, CICIoT2023. | F4: 98.58% accuracy on CICIoT2023 (34 classes) vs 98.26% DNN and 98.25% RNN. | G4: Figures differ between tables; small margin over simple DL baselines.
A5: 4 | B5: Kwari & Rajkumar | C5: 2025 | D5: Evaluate a lightweight soft-voting ensemble under natural imbalance. | E5: Logistic regression, random forest and AdaBoost; 100,000 CICIoT2023 samples (80,000 train, 20,000 test); no resampling. | F5: 76.88% accuracy; macro-F1 0.54 (weighted F1 0.74); flooding and Mirai classes near F1 1.00; rare classes 0.00. | G5: Subset, single split, no mitigation tested.
A6: 5 | B6: Salakhutdinov | C6: n.d. | D6: Critically review AI and DL for IoT network intrusion detection. | E6: Targeted review of architectures, learning strategies and datasets (N-BaIoT, Bot-IoT, TON_IoT, Edge-IIoTset, CICIoT2023). | F6: Conceptual framework separating anomaly detection from intrusion classification, adding explainability, decision support and governed adaptation. | G6: Framework not experimentally validated; venue not stated.
A7: 6 | B7: Imran et al. | C7: 2026 | D7: An explainable IDS comparing six models. | E7: Decision tree, random forest, XGBoost, CNN, LSTM, Transformer on 18,000 samples with six harmonised classes from CICIoT2023 and IoT-23; SHAP and LIME. | F7: LSTM best: 96.02% accuracy, F1 94.69%, ROC-AUC 0.97; top features flow duration, packet rate, bytes per second. | G7: Small sample; qualitative XAI evaluation; some text inconsistencies.
A8: 7 | B8: Hajjouz & Avksentieva | C8: 2024 | D8: Detect DoS, DDoS and Mirai subtypes. | E8: Full CICIoT2023 (45.8 million flows); Spearman clustering to 23 features; class weights; CatBoost; six-fold stratified validation; SHAP. | F8: 99.96% accuracy, precision, recall and F1 on 20 classes; 7.16e-07 s per flow. | G8: Excludes other attack families; macro-F1 not reported.
A9: 8 | B9: Winanto & Idris | C9: 2026 | D9: Review adversarial robustness of DL-based IDS. | E9: PRISMA 2020; 5,890 records, 252 full texts, 216 studies (2020 to March 2026). | F9: FGSM in 76.9% of studies; adversarial training 61.6%; black-box attacks and certified defences rare; CICIoT2023 under 5%. | G9: Single-reviewer screening calibrated on a 50-record sample (kappa 0.81).
A10: 9 | B10: Erskine | C10: 2025 | D10: A combined detection and prevention model. | E10: Deep-learning MLP (DLMIDPSM) trained on over 80% of CICIoT2023. | F10: Accuracy above 85%; 99% precision on Mirai traffic. | G10: Prevention judged by confusion-matrix values, not a blocking test.
A11: 10 | B11: Diana et al. | C11: 2025 | D11: Overview of IDS for network security. | E11: Review of architectures, detection techniques, datasets and deployment in cloud, virtualised, IoT and industrial networks. | F11: Scalability and false alarms remain open; AI/ML and blockchain are promising directions. | G11: Narrative review.
A12: 11 | B12: Yaras & Dener | C12: 2024 | D12: Detect DDoS attacks in a big-data setting. | E12: Hybrid 1D-CNN + LSTM in PySpark with correlation-based feature reduction on CICIoT2023 and TON_IoT; compared with ten algorithms. | F12: 99.995% binary and 99.96% multiclass on CICIoT2023; 98.75% binary on TON_IoT. | G12: Long training on large data; balancing not recorded.
A13: 12 | B13: Mughogho | C13: 2025 | D13: An ML-based IoT IDS using an ensemble. | E13: Mutual-information feature selection; decision tree, random forest, XGBoost and soft voting on CICIoT2023. | F13: 99.80% binary and 99.25% multiclass for the ensemble; members correctly pass only 89-93% of benign flows in binary detection. | G13: MSc project; gains over members only 0.1-0.3 points.
A14: 13 | B14: Ahmed et al. | C14: 2026 | D14: Systematic review of ML-based IDS. | E14: PRISMA; 22,558 records, 125 papers (January 2022 to May 2025). | F14: Five themes (ensemble/hybrid, context-specific, data-centric, deep architectures, trustworthiness); about 2% use XAI, 4% test robustness, none validates in production. | G14: Three databases searched.
A15: 14 | B15: Bunko et al. | C15: 2026 | D15: Survey privacy-preserving federated learning for IDS. | E15: Review of FL-IDS work and protections such as encryption, differential privacy and secure aggregation. | F15: Most work only keeps raw data local; inference and poisoning attacks remain. | G15: Survey, no experiments.
A16: 15 | B16: Mondragon et al. | C16: 2025 | D16: A standard benchmark for flow-based IDS. | E16: 14 datasets with fixed splits and seven algorithm categories compared by macro-F1. | F16: CFC best overall, followed by LCCDE and a fully connected network; LITNET (real traffic) gives the lowest scores. | G16: RBM and GNN methods limited by tuning cost; no single recommended subset.
A17: 16 | B17: Almahaqeri et al. | C17: 2026 | D17: Efficient gradient boosting for edge IDS. | E17: XGBoost, LightGBM, CatBoost on CICIoT2023 for binary, 8-class and 34-class tasks; stratified undersampling; gain-based selection (46 to 23 features). | F17: XGBoost 99.61% accuracy and 0.995 macro-F1 binary at 0.355 microseconds per sample; latency cut 30-51%. | G17: Undersampled evaluation; single dataset; flow-level only.
A18: 17 | B18: Khan et al. | C18: 2026 | D18: A resource-efficient IoT IDS. | E18: BGL-RID (Boruta, greedy forward selection, SMOTE, LightGBM) on TON_IoT, a Raspberry Pi dataset, CICIDS2018 and CICIoT2023. | F18: 98.88% on CICIoT2023; 99.94% CICIDS2018; 99.91% Raspberry Pi; 99.72% binary and 98.94% multiclass on TON_IoT; best efficiency ratio. | G18: SMOTE; small abstract/conclusion mismatch.
... A21: 20 | B21: Mishra & Reddy | C21: 2026 | D21: A federated hybrid DL framework for IoT IDS. | E21: N-BaIoT, CICIoT2023, BoT-IoT; preprocessing, balancing and individual-dataset training with CNN, LSTM, BiLSTM, attention, tiny Transformer, random forest, XGBoost, deep-feature XGBoost. | F21: XGBoost-based models strongest (0.921 accuracy, 0.858 F1, macro-averaged); CICIoT2023 hardest multiclass setting. | G21: Preprint; federated stage not yet run.
B23: Figures are as reported by the authors; blue = entered from the papers. Thirteen papers were read from extracted text focusing on abstracts, methods, results and conclusions.

Sheet Studies
A1: ID | B1: First author | C1: Year | D1: Short title | E1: Venue | F1: Type | G1: Review status | H1: Datasets | I1: Methods / focus | J1: Key findings | K1: Main limitation | L1: Uses CICIoT2023? | M1: ML / ensembles | N1: Deep learning | O1: Explainable AI | P1: Federated / privacy | Q1: Adversarial robustness | R1: Class imbalance | S1: Edge / efficiency | T1: Multiple datasets / benchmarking | U1: Themes covered
A2: 1 | B2: Poltoratskyi & Gavrylenko | C2: 2026 | D2: Evolution of IDS: datasets, DL approaches, architectural challenges | E2: Advanced Information Systems 10(2) | F2: Review | G2: Peer-reviewed journal | H2: Many (ROAD, Edge-IIoT-2022, CICIoT2023, etc.) | I2: Taxonomy, dataset analysis, ML/DL/FL/XAI synthesis 2020-2025 | J2: Benchmarks exceed 98% but imbalance, zero-day detection, scalability and privacy unresolved; recommends MCC, F1, AUC-PR and operational metrics | K2: Narrative synthesis; screening counts not reported | L2: Discussed | M2: 1 | N2: 1 | O2: 1 | P2: 1 | Q2: 1 | R2: 1 | S2: 1 | T2: 1 | U2: =SUM(M2:T2) -> 8
A3: 2 | B3: Rivandi & Oskouei | C3: 2025 | D3: Novel IDS for mobile social networks | E3: J. Soft Computing and Decision Analytics 3(1) | F3: Experimental | G3: Peer-reviewed journal | H3: NS2 simulation (30 nodes) | I3: Social-network metrics (betweenness, degree) with normal-profile thresholds | J3: Single-node detection 99.8-99.9%; detection delay 0.424 s vs 1.051 s for Apriori-based IDS | K3: Small simulation; not IoT benchmark data; unrelated citations in reference list | L3: No | M3: 0 | N3: 0 | O3: 0 | P3: 0 | Q3: 0 | R3: 0 | S3: 0 | T3: 0 | U3: =SUM(M3:T3) -> 0
A4: 3 | B4: Meena & Indian | C4: 2025 | D4: IDS-IoT with enhanced LSTM | E4: Artificial Intelligence and Applications | F4: Experimental | G4: Peer-reviewed journal | H4: KDD-Cup'99, NSL-KDD, UNSW-NB15, CICIoT2023 | I4: Two-layer LSTM vs LR, AdaBoost, DNN, RNN | J4: 98.58% accuracy on CICIoT2023 (34 classes) | K4: Inconsistent figures across tables; small margin over DNN and RNN | L4: Yes | M4: 1 | N4: 1 | O4: 0 | P4: 0 | Q4: 0 | R4: 0 | S4: 0 | T4: 1 | U4: =SUM(M4:T4) -> 3
A5: 4 | B5: Kwari & Rajkumar | C5: 2025 | D5: Enhanced voting ensemble on CICIoT2023 | E5: IGCAI 2025 | F5: Experimental | G5: Conference paper | H5: CICIoT2023 | I5: Soft voting of LR, RF, AdaBoost; no rebalancing | J5: 76.88% accuracy; macro-F1 0.54; rare classes F1 0.00 | K5: 100,000-sample subset; single split; no mitigation tested | L5: Yes | M5: 1 | N5: 0 | O5: 0 | P5: 0 | Q5: 0 | R5: 1 | S5: 0 | T5: 0 | U5: =SUM(M5:T5) -> 2
A6: 5 | B6: Salakhutdinov | C6: n.d. | D6: AI and DL for network intrusion detection in IoT | E6: Not stated | F6: Review | G6: Venue not stated | H6: IoT datasets (N-BaIoT, Bot-IoT, TON_IoT, Edge-IIoTset, CICIoT2023) | I6: Critical review and conceptual framework | J6: Separates anomaly detection from intrusion classification; stresses drift, explainability, defense in depth | K6: Framework not validated; reference list irregularities | L6: Discussed | M6: 1 | N6: 1 | O6: 1 | P6: 1 | Q6: 1 | R6: 1 | S6: 1 | T6: 1 | U6: =SUM(M6:T6) -> 8
A7: 6 | B7: Imran et al. | C7: 2026 | D7: Explainable AI-driven IDS for IoT | E7: J. Computers and Intelligent Systems 4(2) | F7: Experimental | G7: Peer-reviewed journal | H7: CICIoT2023, IoT-23 | I7: DT, RF, XGBoost, CNN, LSTM, Transformer with SHAP and LIME | J7: LSTM best: 96.02% accuracy, F1 94.69%, ROC-AUC 0.97; SHAP/LIME highlight flow duration, packet rate, bytes/s | K7: 18,000-sample, 6-class set; abstract names LR which was not evaluated; qualitative XAI evaluation | L7: Yes | M7: 1 | N7: 1 | O7: 1 | P7: 0 | Q7: 0 | R7: 0 | S7: 1 | T7: 1 | U7: =SUM(M7:T7) -> 5
A8: 7 | B8: Hajjouz & Avksentieva | C8: 2024 | D8: Hierarchical feature selection and CatBoost for DoS/DDoS/Mirai subtypes | E8: Data and Metadata 3 | F8: Experimental | G8: Peer-reviewed journal | H8: CICIoT2023 | I8: Spearman clustering to 23 features; CatBoost; stratified six-fold CV; SHAP | J8: 99.96% on 20 classes; 7.16e-07 s per flow | K8: Excludes other attack families; macro-F1 not reported | L8: Yes | M8: 1 | N8: 0 | O8: 1 | P8: 0 | Q8: 0 | R8: 1 | S8: 1 | T8: 0 | U8: =SUM(M8:T8) -> 4
A9: 8 | B9: Winanto & Idris | C9: 2026 | D9: Adversarial robustness of DL-based IDS: systematic review | E9: IEEE Access 14 | F9: Systematic review | G9: Peer-reviewed journal | H9: 216 studies | I9: PRISMA 2020 review of attacks, defences, datasets | J9: FGSM in 76.9% of studies; adversarial training 61.6%; CICIoT2023 under 5% of corpus | K9: Single-reviewer screening (kappa 0.81 on 50-record sample) | L9: Discussed | M9: 0 | N9: 1 | O9: 0 | P9: 0 | Q9: 1 | R9: 0 | S9: 0 | T9: 1 | U9: =SUM(M9:T9) -> 3
A10: 9 | B10: Erskine | C10: 2025 | D10: Real-time IDPS on CICIoT dataset based on deep learning | E10: Applied System Innovation 8:52 | F10: Experimental | G10: Peer-reviewed journal | H10: CICIoT2023 | I10: DLMLP detection and prevention model | J10: Accuracy above 85%; 99% precision on Mirai | K10: Prevention judged by confusion matrix; modest accuracy | L10: Yes | M10: 1 | N10: 1 | O10: 0 | P10: 0 | Q10: 0 | R10: 0 | S10: 0 | T10: 0 | U10: =SUM(M10:T10) -> 2
A11: 10 | B11: Diana et al. | C11: 2025 | D11: Overview on IDS for computer networking security | E11: Computers 14:87 | F11: Review | G11: Peer-reviewed journal | H11: General | I11: Architectures, detection techniques, environments; AI/ML and blockchain | J11: Scalability and false positives/negatives remain open | K11: Read from abstract and key sections | L11: No | M11: 1 | N11: 0 | O11: 0 | P11: 0 | Q11: 0 | R11: 0 | S11: 0 | T11: 1 | U11: =SUM(M11:T11) -> 2
A12: 11 | B12: Yaras & Dener | C12: 2024 | D12: IoT-based IDS using a new hybrid DL algorithm | E12: Electronics 13:1053 | F12: Experimental | G12: Peer-reviewed journal | H12: CICIoT2023, TON_IoT | I12: 1D-CNN + LSTM in PySpark; compared with ten algorithms | J12: 99.995% binary and 99.96% multiclass on CICIoT2023; 98.75% binary on TON_IoT | K12: Long training on large data; balancing not recorded | L12: Yes | M12: 1 | N12: 1 | O12: 0 | P12: 0 | Q12: 0 | R12: 0 | S12: 0 | T12: 1 | U12: =SUM(M12:T12) -> 3
A13: 12 | B13: Mughogho | C13: 2025 | D13: Enhancing IoT network security with ML | E13: National College of Ireland (MSc project) | F13: Experimental | G13: MSc project | H13: CICIoT2023 | I13: Mutual-information selection; DT, RF, XGBoost, soft voting | J13: 99.80% binary; 99.25% multiclass | K13: Benign true-negative rate 89-93% for members; ensemble gains 0.1-0.3 points | L13: Yes | M13: 1 | N13: 0 | O13: 0 | P13: 0 | Q13: 0 | R13: 0 | S13: 0 | T13: 0 | U13: =SUM(M13:T13) -> 1
A14: 13 | B14: Ahmed et al. | C14: 2026 | D14: Systematic literature review on ML for IDS | E14: Future Internet 18:470 | F14: Systematic review | G14: Peer-reviewed journal | H14: 125 studies | I14: PRISMA review, five themes | J14: About 2% use XAI, 4% test robustness, none validated in production | K14: Three databases searched | L14: Discussed | M14: 1 | N14: 1 | O14: 1 | P14: 0 | Q14: 1 | R14: 1 | S14: 0 | T14: 1 | U14: =SUM(M14:T14) -> 6
A15: 14 | B15: Bunko et al. | C15: 2026 | D15: Privacy-preserving federated learning for IDS | E15: Artificial Intelligence Review 59:125 | F15: Survey | G15: Peer-reviewed journal | H15: FL-IDS literature | I15: Encryption, differential privacy, secure aggregation | J15: Most work only keeps data local; inference and poisoning risks remain | K15: Read from abstract and key sections | L15: Discussed | M15: 0 | N15: 0 | O15: 0 | P15: 1 | Q15: 1 | R15: 0 | S15: 0 | T15: 0 | U15: =SUM(M15:T15) -> 2
A16: 15 | B16: Mondragon et al. | C16: 2025 | D16: Advanced IDS: comparative study of datasets and ML algorithms | E16: Applied Intelligence 55:608 | F16: Benchmark | G16: Peer-reviewed journal | H16: 14 flow datasets | I16: Seven algorithm categories compared by macro-F1 | J16: CFC best macro-F1; LITNET (real traffic) lowest | K16: RBM and GNN methods limited by tuning cost | L16: Not recorded | M16: 1 | N16: 1 | O16: 0 | P16: 0 | Q16: 0 | R16: 1 | S16: 0 | T16: 1 | U16: =SUM(M16:T16) -> 4
A17: 16 | B17: Almahaqeri et al. | C17: 2026 | D17: Optimized gradient boosting for IoT IDS on CICIoT2023 | E17: Scientific Reports | F17: Experimental | G17: Peer-reviewed journal | H17: CICIoT2023 | I17: XGBoost, LightGBM, CatBoost; undersampling; gain-based selection | J17: XGBoost 99.61% binary; features 46 to 23 cut latency 30-51% | K17: Undersampled evaluation; single dataset; flow-level only | L17: Yes | M17: 1 | N17: 0 | O17: 0 | P17: 0 | Q17: 0 | R17: 1 | S17: 1 | T17: 0 | U17: =SUM(M17:T17) -> 3
A18: 17 | B18: Khan et al. | C18: 2026 | D18: Resource-efficient IoT IDS with hybrid feature selection | E18: Scientific Reports | F18: Experimental | G18: Peer-reviewed journal | H18: TON_IoT, Raspberry Pi, CICIDS2018, CICIoT2023 | I18: BGL-RID (Boruta, greedy selection, SMOTE, LightGBM) | J18: 98.88% on CICIoT2023; 99.94% on CICIDS2018 | K18: SMOTE; abstract/conclusion mismatch (98.94 vs 98.93) | L18: Yes | M18: 1 | N18: 0 | O18: 0 | P18: 0 | Q18: 0 | R18: 1 | S18: 1 | T18: 1 | U18: =SUM(M18:T18) -> 4
... A21: 20 | B21: Mishra & Reddy | C21: 2026 | D21: Federated hybrid DL framework for IoT IDS | E21: Research Square preprint | F21: Experimental | G21: Preprint | H21: N-BaIoT, CICIoT2023, BoT-IoT | I21: Hybrid deep models, XGBoost, deep-feature XGBoost; federated planned | J21: XGBoost-based models strongest; CICIoT2023 hardest; macro avg 0.921 accuracy / 0.858 F1 | K21: Federated stage not run | L21: Yes | M21: 1 | N21: 1 | O21: 0 | P21: 1 | Q21: 0 | R21: 1 | S21: 0 | T21: 1 | U21: =SUM(M21:T21) -> 5

Sheet Reviews
A1: Study | B1: Period covered | C1: Records screened | D1: Full texts / included | E1: Method | F1: Scope | G1: Key conclusions
A2: Poltoratskyi & Gavrylenko (2026) | B2: 2020-2025 | C2: Not reported | D2: Not reported | E2: Review (PRISMA stated) | F2: IDS evolution, taxonomy, datasets, DL/FL/XAI | G2: Benchmarks exceed 98%; imbalance, zero-day, scalability, privacy open
A3: Salakhutdinov (n.d.) | B3: Not stated | C3: Not applicable | D3: Not applicable | E3: Targeted critical review (no PRISMA counts) | F3: AI/DL for IoT NIDS; conceptual framework | G3: Benchmark success does not equal robustness; drift, explainability, defense in depth
A4: Winanto & Idris (2026) | B4: Jan 2020 - Mar 2026 | C4: 5890 | D4: 252 full texts; 216 included | E4: PRISMA 2020 systematic review | F4: Adversarial robustness of DL-IDS | G4: White-box attacks and adversarial training dominate; CICIoT2023 under 5% of corpus; 12 gaps
A5: Diana et al. (2025) | B5: Not recorded | C5: Not recorded | D5: Not recorded | E5: Narrative review | F5: Architectures, techniques, datasets, environments | G5: Scalability and false alarms; AI/ML and blockchain as directions
A6: Ahmed et al. (2026) | B6: Jan 2022 - May 2025 | C6: 22558 | D6: 125 | E6: PRISMA systematic review | F6: ML-based IDS | G6: Five themes; about 2% XAI, 4% robustness; none validated in production
A7: Bunko et al. (2026) | B7: Not recorded | C7: Not recorded | D7: Not recorded | E7: Survey | F7: Privacy-preserving FL for IDS | G7: Most FL-IDS work stops at data locality; inference and poisoning remain
A8: Mallidi & Ramisetty (2025) | B8: Not recorded | C8: Not recorded | D8: Not recorded | E8: Systematic literature review | F8: Training and deployment strategies for AI-IDS in IoT | G8: FL and hybrid cloud-fog-edge deployment improve scalability and privacy
A9: Hozouri et al. (2025) | B9: Not recorded | C9: Not recorded | D9: Not recorded | E9: Survey | F9: IDS types, ML/DL, legacy datasets | G9: Labelled-data dependence and class imbalance
A11: Screening yield (included / screened)
A12: Review | B12: Screened | C12: Included | D12: Yield
A13: Winanto & Idris (2026) | B13: =C4 -> 5890 | C13: 216 | D13: =C13/B13 -> 0.036672326
A14: Ahmed et al. (2026) | B14: =C6 -> 22558 | C14: =D6 -> 125 | D14: =C14/B14 -> 0.0055412714

Sheet Datasets
A1: Dataset | B1: Year | C1: Characteristics as reported | D1: Studies listing it (Datasets column) | E1: Search text
A2: CICIoT2023 | B2: 2023 | C2: 105 IoT devices; 47 features; 33 attack types plus benign (34 classes); extreme imbalance; about 45.8 million flows in full set | D2: =COUNTIF(Studies!$H$2:$H$21,"*"&E2&"*") -> 12 | E2: CICIoT2023
A3: KDD-Cup'99 | B3: 1999 | C3: 41 features; about 4.9 million records; criticised as outdated and synthetic | D3: =COUNTIF(Studies!$H$2:$H$21,"*"&E3&"*") -> 2 | E3: KDD-Cup'99
A4: NSL-KDD | B4: 2009 | C4: 148,517 records; 41 features; redundancy reduced | D4: =COUNTIF(Studies!$H$2:$H$21,"*"&E4&"*") -> 1 | E4: NSL-KDD
A5: UNSW-NB15 | B5: 2015 | C5: 257,673 records; 49 features (as described by Meena & Indian) | D5: =COUNTIF(Studies!$H$2:$H$21,"*"&E5&"*") -> 2 | E5: UNSW-NB15
A6: TON_IoT | B6: 2020 | C6: Heterogeneous edge-fog-cloud IoT telemetry and network data | D6: =COUNTIF(Studies!$H$2:$H$21,"*"&E6&"*") -> 3 | E6: TON_IoT
A7: IoT-23 | B7: 2020 | C7: IoT network captures (used with CICIoT2023 by Imran et al.) | D7: =COUNTIF(Studies!$H$2:$H$21,"*"&E7&"*") -> 1 | E7: IoT-23
A8: N-BaIoT | B8: 2018 | C8: Commercial IoT devices infected with Mirai/BASHLITE | D8: =COUNTIF(Studies!$H$2:$H$21,"*"&E8&"*") -> 2 | E8: N-BaIoT
A9: BoT-IoT | B9: 2019 | C9: Botnet-oriented IoT testbed; class imbalance | D9: =COUNTIF(Studies!$H$2:$H$21,"*"&E9&"*") -> 2 | E9: BoT-IoT
A10: CICIDS2018 | B10: 2018 | C10: Enterprise-style benchmark used by Khan et al. | D10: =COUNTIF(Studies!$H$2:$H$21,"*"&E10&"*") -> 1 | E10: CICIDS2018
A11: CIC-IDS2017 | B11: 2017 | C11: Enterprise-style benchmark named by Hozouri et al. | D11: =COUNTIF(Studies!$H$2:$H$21,"*"&E11&"*") -> 1 | E11: CIC-IDS2017
A13: Note: counts cover the Datasets column only (what each study uses or evaluates). Year values are as I recall or as stated in the papers; verify before citing.

Sheet Gaps
A1: # | B1: Research gap | C1: Evidence | D1: Study IDs raising it | E1: Number of studies
A2: 1 | B2: Standardised CICIoT2023 protocol (label set, splits, metrics) | C2: Accuracy ranges from 76.88% to 99.995% depending on setup | D2: 1, 4, 15 | E2: =LEN(D2)-LEN(SUBSTITUTE(D2,",",""))+1 -> 3
A3: 2 | B3: Cross-dataset and cross-device generalisation | C3: Best method changes by dataset; no study trains on one dataset and tests on another | D3: 1, 5, 15 | E3: =LEN(D3)-LEN(SUBSTITUTE(D3,",",""))+1 -> 3
A4: 3 | B4: Rare-class detection | C4: Rare classes F1 0.00 without mitigation; rebalancing choices change results | D4: 1, 4, 13, 16 | E4: =LEN(D4)-LEN(SUBSTITUTE(D4,",",""))+1 -> 4
A5: 4 | B5: Fair deep vs tree comparisons | C5: Two head-to-head studies disagree | D5: 6, 15, 20 | E5: =LEN(D5)-LEN(SUBSTITUTE(D5,",",""))+1 -> 3
A6: 5 | B6: Quantified explainability | C6: SHAP/LIME used qualitatively; top features differ between studies | D6: 1, 5, 6, 7, 13 | E6: =LEN(D6)-LEN(SUBSTITUTE(D6,",",""))+1 -> 5
A7: 6 | B7: Resource-aware evaluation on edge hardware | C7: Memory, energy and edge tests rarely reported | D7: 1, 5, 16, 17 | E7: =LEN(D7)-LEN(SUBSTITUTE(D7,",",""))+1 -> 4
A8: 7 | B8: Concept drift and adversarial robustness | C8: Few studies test robustness; CICIoT2023 under 5% of robustness corpus | D8: 1, 5, 8, 13 | E8: =LEN(D8)-LEN(SUBSTITUTE(D8,",",""))+1 -> 4
A9: 8 | B9: Privacy beyond data locality in federated IDS | C9: Differential privacy and secure aggregation rare; federated stage of one preprint not run | D9: 5, 14, 18, 20 | E9: =LEN(D9)-LEN(SUBSTITUTE(D9,",",""))+1 -> 4
A10: 9 | B10: Production and streaming validation | C10: None of 125 reviewed papers validates in production | D10: 13, 16 | E10: =LEN(D10)-LEN(SUBSTITUTE(D10,",",""))+1 -> 2
A11: 10 | B11: Measured prevention/response | C11: Prevention claims judged only by classification metrics | D11: 9 | E11: =LEN(D11)-LEN(SUBSTITUTE(D11,",",""))+1 -> 1
A12: 11 | B12: Realistic operational benchmarks | C12: Real-traffic LITNET gives lowest macro-F1 | D12: 15 | E12: =LEN(D12)-LEN(SUBSTITUTE(D12,",",""))+1 -> 1

Sheet References
A1: ID | B1: Citation | C1: DOI
A2: 1 | B2: Poltoratskyi, V., & Gavrylenko, S. (2026). The Evolution of Intrusion Detection Systems: A Comprehensive Review of Modern Datasets, Deep Learning Approaches, and Architectural Challenges. Advanced Information Systems, 10(2), 100-116. | C2: 10.20998/2522-9052.2026.2.11
A3: 2 | B3: Rivandi, E., & Oskouei, R. J. (2025). A Novel Approach for Developing Intrusion Detection Systems in Mobile Social Networks. J. Soft Computing and Decision Analytics, 3(1), 158-170. | C3: 10.31181/jscda31202576
A4: 3 | B4: Meena, G., & Indian, A. (2025). IDS-IoT: Intrusion Detection System for the Internet of Things Using Enhanced Long-Short Term Memory. Artificial Intelligence and Applications. | C4: 10.47852/bonviewAIA52025066
A5: 4 | B5: Kwari, M. I., & Rajkumar, N. (2025). An Enhanced Voting Ensemble Model for IoT Intrusion Detection Using the CICIoT2023 Dataset. IGCAI 2025, 67-77. | C5: 10.63169/IGCAI2025.p9
A6: 5 | B6: Salakhutdinov, R. (n.d.). Artificial Intelligence and Deep Learning for Network Intrusion Detection in Internet of Things Environments. Venue not stated. | C6: Not stated
A7: 6 | B7: Imran, S., Yousaf, M., Shabeer, Z., Sarwar, M., & Zainab, N. (2026). An Explainable AI-Driven Intrusion Detection Framework for IoT Networks Using Deep Learning and Machine Learning Models. J. Computers and Intelligent Systems, 4(2), 99-116. | C7: Not stated
A8: 7 | B8: Hajjouz, A., & Avksentieva, E. (2024). Optimizing Intrusion Detection for DoS, DDoS, and Mirai Attacks Subtypes Using Hierarchical Feature Selection and CatBoost on the CICIoT2023 Dataset. Data and Metadata, 3, 577. | C8: 10.56294/dm2024.577
A9: 8 | B9: Winanto, E. A., & Idris, M. Y. (2026). Adversarial Robustness of Deep Learning-Based Intrusion Detection Systems: A Systematic Literature Review. IEEE Access, 14. | C9: 10.1109/ACCESS.2026.3733985
A10: 9 | B10: Erskine, S. K. (2025). Real-Time Large-Scale Intrusion Detection and Prevention System (IDPS) CICIoT Dataset Traffic Assessment Based on Deep Learning. Applied System Innovation, 8, 52. | C10: 10.3390/asi8020052
A11: 10 | B11: Diana, L., Dini, P., & Paolini, D. (2025). Overview on Intrusion Detection Systems for Computers Networking Security. Computers, 14, 87. | C11: 10.3390/computers14030087
A12: 11 | B12: Yaras, S., & Dener, M. (2024). IoT-Based Intrusion Detection System Using New Hybrid Deep Learning Algorithm. Electronics, 13, 1053. | C12: 10.3390/electronics13061053
A13: 12 | B13: Mughogho, E. (2025). Enhancing IoT Network Security Through Intrusion Detection Using Machine Learning. MSc research project, National College of Ireland. | C13: Not applicable
... A21: 20 | B21: Mishra, S., & Reddy, R. V. S. (2026). Federated Hybrid Deep Learning Framework for IoT Intrusion Detection Using N-BaIoT, CICIoT2023, and BoT-IoT Datasets (preprint). Research Square. | C21: 10.21203/rs.3.rs-10580856/v1

Sheet This_Study
A1: This study: own deep-learning experiments on CICIoT2023
A2: Not part of the 20-study corpus: Summary, Studies, Datasets and Gaps counts exclude it. Source: DeepLearning_notebook.ipynb. Blue = value or judgement entered by me; black = formula or label.
A4: 1. Study record (same fields as the Studies sheet)
A5: Field | B5: Entry
A6: Type | B6: Experimental (own work, not in the 20-study corpus)
A7: Aim | B7: Compare plain and regularised MLPs with recurrent (GRU, LSTM) and attention (Transformer) models for 8-class intrusion detection on CICIoT2023.
A8: Dataset | B8: CICIoT2023 pre-split train (1,073,851 flows) and test (268,463 flows) files; 39 numeric flow features; 8 classes: Benign, BruteForce, DDoS, DoS, Mirai, Recon, Spoofing, Web-based.
A9: Data preparation | B9: Exact duplicates removed from the training data (84,370 rows); balanced to 10,000 flows per class; 80/20 stratified train/validation split; StandardScaler fitted on the training part. Test set used as supplied.
A10: Methods / focus | B10: Seven models: DNN, DNN + Dropout, DNN + L2, a combined regularised DNN, GRU, LSTM and a feature-token Transformer encoder (section 2).
A11: Evaluation | B11: Accuracy, macro precision, macro recall, macro-F1, macro specificity, training time and per-class reports on the natural-distribution test set.
A12: Key findings | B12: ="Highest accuracy "&TEXT(MAX(E19:E25),"0.00%")&" ("&INDEX(A19:A25,MATCH(MAX(E19:E25),E19:E25,0))&"). Transformer "&TEXT(E25,"0.00%")&" accuracy and "&TEXT(F25,"0.000")&" macro-F1; GRU "&TEXT(E23,"0.00%")&" and "&TEXT(F23,"0.000")&"; LSTM "&TEXT(E24,"0.00%")&" and "&TEXT(F24,"0.000")&". BruteForce and Web-based are the hardest classes for every model." -> Highest accuracy 75.44% (DNN). Transformer 72.53% accuracy and 0.626 macro-F1; GRU 69.82% and 0.587; LSTM 55.24% and 0.457. BruteForce and Web-based are the hardest classes for every model.
A13: Main limitation | B13: One run per model; GRU and Transformer ran to their epoch limits with validation loss still falling, and the saved LSTM log shows 5 of 20 epochs; no tree-based baseline; one dataset; no inference-latency measurement.
A14: Uses CICIoT2023? | B14: Yes
A15: Earlier version | B15: The previous notebook version used a CNN model where the GRU now sits and an earlier Transformer configuration. Their results are not recorded here.
A17: 2. Models and results (8 classes; natural-distribution test set of 268,463 flows)
A18: Model | B18: Configuration | C18: Training setup | D18: Parameters | E18: Accuracy | F18: Macro-F1 | G18: Training time (s) | H18: Accuracy rank
A19: DNN | B19: MLP: Dense 128-64-32 (ReLU) and softmax output; Adam. | C19: 20 epochs, batch 256, no callbacks. | D19: 15720 | E19: 0.7544 | F19: 0.6346 | G19: 19.48 | H19: =RANK(E19,$E$19:$E$25) -> 1
A20: DNN + Dropout | B20: MLP as above with Dropout 0.30 after the first two dense layers. | C20: 20 epochs, batch 256, no callbacks. | D20: 15720 | E20: 0.7373 | F20: 0.621 | G20: 21.84 | H20: =RANK(E20,$E$19:$E$25) -> 4
A21: DNN + L2 | B21: MLP as above with L2 (0.001) on the first two dense layers. | C21: 20 epochs, batch 256, no callbacks. | D21: 15720 | E21: 0.7508 | F21: 0.6305 | G21: 18.46 | H21: =RANK(E21,$E$19:$E$25) -> 2
A22: Proposed DNN | B22: MLP with L2 (0.001), batch normalisation after the first layer and dropout 0.30 / 0.30 / 0.20. | C22: Up to 20 epochs, early stopping (patience 4) and learning-rate reduction. | D22: 16232 | E22: 0.7407 | F22: 0.6226 | G22: 25.7 | H22: =RANK(E22,$E$19:$E$25) -> 3
A23: GRU | B23: Recurrent: the 39 features are fed as 39 time steps of one value. GRU 64 (sequences), Dropout 0.20, GRU 32, Dense 64, Dropout 0.20, softmax. Replaces the CNN model of the earlier version. | C23: Up to 20 epochs, batch 256, early stopping (patience 5) and learning-rate reduction; ran all 20 epochs. | D23: 24904 | E23: 0.6982 | F23: 0.5868 | G23: 668.69 | H23: =RANK(E23,$E$19:$E$25) -> 6
A24: LSTM | B24: Recurrent: same input as the GRU. LSTM 64 (sequences), Dropout 0.30, LSTM 32, Dropout 0.30, Dense 64, softmax. | C24: Up to 20 epochs, same callbacks as the GRU; the saved log shows 5 epochs. | D24: 31944 | E24: 0.5524 | F24: 0.4571 | G24: 173.61 | H24: =RANK(E24,$E$19:$E$25) -> 7
A25: Transformer | B25: Attention: one learnable 64-dimensional token per feature, position embedding and a CLS token; 2 pre-norm encoder blocks, 4 heads, feed-forward 128 (GELU), dropout 0.10; Dense 64 head; AdamW (learning rate 1e-4, weight decay 1e-4). | C25: Up to 25 epochs, batch 256, early stopping (patience 5) and learning-rate reduction (patience 3); ran all 25 epochs. | D25: 76808 | E25: 0.7253 | F25: 0.6263 | G25: 3497.91 | H25: =RANK(E25,$E$19:$E$25) -> 5
A27: 3. Review themes (same 8 themes and 1/0 flags as the Studies sheet)
A28: Theme | B28: Basis for the flag | C28: Corpus coverage | D28: This study (1 = covered)
A29: =Summary!A22 -> ML / ensembles | B29: No tree-based or ensemble model. | C29: ="Covered by "&Summary!B22&" of "&Summary!B4&" corpus studies ("&TEXT(Summary!C22,"0%")&")" -> Covered by 17 of 20 corpus studies (85%) | D29: 0
A30: =Summary!A23 -> Deep learning | B30: MLP, GRU, LSTM and Transformer models. | C30: ="Covered by "&Summary!B23&" of "&Summary!B4&" corpus studies ("&TEXT(Summary!C23,"0%")&")" -> Covered by 12 of 20 corpus studies (60%) | D30: 1
A31: =Summary!A24 -> Explainable AI | B31: No SHAP, LIME or other explanation method. | C31: ="Covered by "&Summary!B24&" of "&Summary!B4&" corpus studies ("&TEXT(Summary!C24,"0%")&")" -> Covered by 5 of 20 corpus studies (25%) | D31: 0
A32: =Summary!A25 -> Federated / privacy | B32: Centralised training only. | C32: ="Covered by "&Summary!B25&" of "&Summary!B4&" corpus studies ("&TEXT(Summary!C25,"0%")&")" -> Covered by 5 of 20 corpus studies (25%) | D32: 0
A33: =Summary!A26 -> Adversarial robustness | B33: No adversarial or drift testing. | C33: ="Covered by "&Summary!B26&" of "&Summary!B4&" corpus studies ("&TEXT(Summary!C26,"0%")&")" -> Covered by 5 of 20 corpus studies (25%) | D33: 0
A34: =Summary!A27 -> Class imbalance | B34: Balanced 10,000-per-class training sample; per-class and macro metrics on the natural-distribution test set. | C34: ="Covered by "&Summary!B27&" of "&Summary!B4&" corpus studies ("&TEXT(Summary!C27,"0%")&")" -> Covered by 10 of 20 corpus studies (50%) | D34: 1
A35: =Summary!A28 -> Edge / efficiency | B35: Parameter counts and CPU training time only; no inference latency or memory. | C35: ="Covered by "&Summary!B28&" of "&Summary!B4&" corpus studies ("&TEXT(Summary!C28,"0%")&")" -> Covered by 7 of 20 corpus studies (35%) | D35: 0
A36: =Summary!A29 -> Multiple datasets / benchmarking | B36: CICIoT2023 only; no second dataset. | C36: ="Covered by "&Summary!B29&" of "&Summary!B4&" corpus studies ("&TEXT(Summary!C29,"0%")&")" -> Covered by 13 of 20 corpus studies (65%) | D36: 0
A37: Themes covered | C37: ="Corpus average: "&TEXT(Summary!B16,"0.0")&" themes per study" -> Corpus average: 3.7 themes per study | D37: =SUM(D29:D36) -> 2
A39: 4. Relation to the research gaps (Gaps sheet)
A40: Gap | B40: Research gap | C40: What this study shows | D40: Status
A41: ="Gap "&Gaps!A2 -> Gap 1 | B41: =Gaps!B2 -> Standardised CICIoT2023 protocol (label set, splits, metrics) | C41: Adds one more setup (8 attack families, 10,000-per-class training sample, natural test set). Accuracy here sits well below the undersampled-test results in the corpus, as the gap describes. | D41: Illustrates
A42: ="Gap "&Gaps!A3 -> Gap 2 | B42: =Gaps!B3 -> Cross-dataset and cross-device generalisation | C42: Single dataset; no cross-dataset or cross-device test. | D42: Not addressed
A43: ="Gap "&Gaps!A4 -> Gap 3 | B43: =Gaps!B4 -> Rare-class detection | C43: BruteForce and Web-based stay hardest for every model even with balanced training: on the natural test set precision is low and always below recall (SOTA workbook, Own_Results section 5). | D43: Illustrates
A44: ="Gap "&Gaps!A5 -> Gap 4 | B44: =Gaps!B5 -> Fair deep vs tree comparisons | C44: Deep models only; there is no tree-based baseline on the same split, so this study cannot add to the comparison. | D44: Not addressed
...
